2021-11-21 14:23:43,786 INFO: Microblog startup [in /home/zeaiter/Documents/Web Tutorials/microblog/app/__init__.py:44] 

2021-11-21 14:23:49,804 ERROR: Exception on /edit_profile [POST] [in /home/zeaiter/Documents/Web Tutorials/microblog/venv/lib/python3.9/site-packages/flask/app.py:1457] 
Traceback (most recent call last):
  File "/home/zeaiter/Documents/Web Tutorials/microblog/venv/lib/python3.9/site-packages/sqlalchemy/engine/base.py", line 1799, in _execute_context
    self.dialect.do_execute(
  File "/home/zeaiter/Documents/Web Tutorials/microblog/venv/lib/python3.9/site-packages/sqlalchemy/engine/default.py", line 717, in do_execute
    cursor.execute(statement, parameters)
sqlite3.IntegrityError: UNIQUE constraint failed: user.username

The above exception was the direct cause of the following exception:

Traceback (most recent call last):
  File "/home/zeaiter/Documents/Web Tutorials/microblog/venv/lib/python3.9/site-packages/flask/app.py", line 2073, in wsgi_app
    response = self.full_dispatch_request()
  File "/home/zeaiter/Documents/Web Tutorials/microblog/venv/lib/python3.9/site-packages/flask/app.py", line 1518, in full_dispatch_request
    rv = self.handle_user_exception(e)
  File "/home/zeaiter/Documents/Web Tutorials/microblog/venv/lib/python3.9/site-packages/flask/app.py", line 1516, in full_dispatch_request
    rv = self.dispatch_request()
  File "/home/zeaiter/Documents/Web Tutorials/microblog/venv/lib/python3.9/site-packages/flask/app.py", line 1502, in dispatch_request
    return self.ensure_sync(self.view_functions[rule.endpoint])(**req.view_args)
  File "/home/zeaiter/Documents/Web Tutorials/microblog/venv/lib/python3.9/site-packages/flask_login/utils.py", line 272, in decorated_view
    return func(*args, **kwargs)
  File "/home/zeaiter/Documents/Web Tutorials/microblog/app/routes.py", line 84, in edit_profile
    db.session.commit()
  File "<string>", line 2, in commit
  File "/home/zeaiter/Documents/Web Tutorials/microblog/venv/lib/python3.9/site-packages/sqlalchemy/orm/session.py", line 1428, in commit
    self._transaction.commit(_to_root=self.future)
  File "/home/zeaiter/Documents/Web Tutorials/microblog/venv/lib/python3.9/site-packages/sqlalchemy/orm/session.py", line 829, in commit
    self._prepare_impl()
  File "/home/zeaiter/Documents/Web Tutorials/microblog/venv/lib/python3.9/site-packages/sqlalchemy/orm/session.py", line 808, in _prepare_impl
    self.session.flush()
  File "/home/zeaiter/Documents/Web Tutorials/microblog/venv/lib/python3.9/site-packages/sqlalchemy/orm/session.py", line 3340, in flush
    self._flush(objects)
  File "/home/zeaiter/Documents/Web Tutorials/microblog/venv/lib/python3.9/site-packages/sqlalchemy/orm/session.py", line 3480, in _flush
    transaction.rollback(_capture_exception=True)
  File "/home/zeaiter/Documents/Web Tutorials/microblog/venv/lib/python3.9/site-packages/sqlalchemy/util/langhelpers.py", line 70, in __exit__
    compat.raise_(
  File "/home/zeaiter/Documents/Web Tutorials/microblog/venv/lib/python3.9/site-packages/sqlalchemy/util/compat.py", line 207, in raise_
    raise exception
  File "/home/zeaiter/Documents/Web Tutorials/microblog/venv/lib/python3.9/site-packages/sqlalchemy/orm/session.py", line 3440, in _flush
    flush_context.execute()
  File "/home/zeaiter/Documents/Web Tutorials/microblog/venv/lib/python3.9/site-packages/sqlalchemy/orm/unitofwork.py", line 456, in execute
    rec.execute(self)
  File "/home/zeaiter/Documents/Web Tutorials/microblog/venv/lib/python3.9/site-packages/sqlalchemy/orm/unitofwork.py", line 630, in execute
    util.preloaded.orm_persistence.save_obj(
  File "/home/zeaiter/Documents/Web Tutorials/microblog/venv/lib/python3.9/site-packages/sqlalchemy/orm/persistence.py", line 236, in save_obj
    _emit_update_statements(
  File "/home/zeaiter/Documents/Web Tutorials/microblog/venv/lib/python3.9/site-packages/sqlalchemy/orm/persistence.py", line 1000, in _emit_update_statements
    c = connection._execute_20(
  File "/home/zeaiter/Documents/Web Tutorials/microblog/venv/lib/python3.9/site-packages/sqlalchemy/engine/base.py", line 1611, in _execute_20
    return meth(self, args_10style, kwargs_10style, execution_options)
  File "/home/zeaiter/Documents/Web Tutorials/microblog/venv/lib/python3.9/site-packages/sqlalchemy/sql/elements.py", line 325, in _execute_on_connection
    return connection._execute_clauseelement(
  File "/home/zeaiter/Documents/Web Tutorials/microblog/venv/lib/python3.9/site-packages/sqlalchemy/engine/base.py", line 1478, in _execute_clauseelement
    ret = self._execute_context(
  File "/home/zeaiter/Documents/Web Tutorials/microblog/venv/lib/python3.9/site-packages/sqlalchemy/engine/base.py", line 1842, in _execute_context
    self._handle_dbapi_exception(
  File "/home/zeaiter/Documents/Web Tutorials/microblog/venv/lib/python3.9/site-packages/sqlalchemy/engine/base.py", line 2023, in _handle_dbapi_exception
    util.raise_(
  File "/home/zeaiter/Documents/Web Tutorials/microblog/venv/lib/python3.9/site-packages/sqlalchemy/util/compat.py", line 207, in raise_
    raise exception
  File "/home/zeaiter/Documents/Web Tutorials/microblog/venv/lib/python3.9/site-packages/sqlalchemy/engine/base.py", line 1799, in _execute_context
    self.dialect.do_execute(
  File "/home/zeaiter/Documents/Web Tutorials/microblog/venv/lib/python3.9/site-packages/sqlalchemy/engine/default.py", line 717, in do_execute
    cursor.execute(statement, parameters)
sqlalchemy.exc.IntegrityError: (sqlite3.IntegrityError) UNIQUE constraint failed: user.username
[SQL: UPDATE user SET username=?, about_me=? WHERE user.id = ?]
[parameters: ('abram', '', 2)]
(Background on this error at: https://sqlalche.me/e/14/gkpj)
2021-11-21 14:24:24,377 INFO: Microblog startup [in /home/zeaiter/Documents/Web Tutorials/microblog/app/__init__.py:44] 

2021-11-28 16:54:23,889 INFO: Microblog startup [in /home/zeaiter/Documents/Web Tutorials/microblog/app/__init__.py:44] 

2021-11-28 16:55:13,158 INFO: Microblog startup [in /home/zeaiter/Documents/Web Tutorials/microblog/app/__init__.py:44] 

2021-11-28 16:56:13,347 INFO: Microblog startup [in /home/zeaiter/Documents/Web Tutorials/microblog/app/__init__.py:44] 

2021-11-28 16:56:43,891 INFO: Microblog startup [in /home/zeaiter/Documents/Web Tutorials/microblog/app/__init__.py:44] 

2021-11-28 17:00:13,919 INFO: Microblog startup [in /home/zeaiter/Documents/Web Tutorials/microblog/app/__init__.py:44] 

2021-11-28 17:02:02,463 INFO: Microblog startup [in /home/zeaiter/Documents/Web Tutorials/microblog/app/__init__.py:44] 

2021-11-28 17:07:24,747 INFO: Microblog startup [in /home/zeaiter/Documents/Web Tutorials/microblog/app/__init__.py:44] 

2021-11-28 17:08:09,260 INFO: Microblog startup [in /home/zeaiter/Documents/Web Tutorials/microblog/app/__init__.py:44] 

2021-11-28 17:27:25,732 INFO: Microblog startup [in /home/zeaiter/Documents/Web Tutorials/microblog/app/__init__.py:44] 

2021-11-28 17:28:38,216 INFO: Microblog startup [in /home/zeaiter/Documents/Web Tutorials/microblog/app/__init__.py:44] 

2021-11-28 17:36:09,066 INFO: Microblog startup [in /home/zeaiter/Documents/Web Tutorials/microblog/app/__init__.py:44] 

2021-11-28 17:38:45,766 INFO: Microblog startup [in /home/zeaiter/Documents/Web Tutorials/microblog/app/__init__.py:44] 

2021-12-05 12:19:19,912 INFO: Microblog startup [in /home/zeaiter/Documents/Web Tutorials/microblog/app/__init__.py:44] 

